[2025-01-24T00:26:04.192+0000] {local_task_job_runner.py:123} INFO - ::group::Pre task execution logs
[2025-01-24T00:26:04.206+0000] {taskinstance.py:2612} INFO - Dependencies all met for dep_context=non-requeueable deps ti=<TaskInstance: nasa_dag.extract_data manual__2025-01-22T03:28:41.301915+00:00 [queued]>
[2025-01-24T00:26:04.215+0000] {taskinstance.py:2612} INFO - Dependencies all met for dep_context=requeueable deps ti=<TaskInstance: nasa_dag.extract_data manual__2025-01-22T03:28:41.301915+00:00 [queued]>
[2025-01-24T00:26:04.216+0000] {taskinstance.py:2865} INFO - Starting attempt 1 of 2
[2025-01-24T00:26:04.227+0000] {taskinstance.py:2888} INFO - Executing <Task(BashOperator): extract_data> on 2025-01-22 03:28:41.301915+00:00
[2025-01-24T00:26:04.232+0000] {warnings.py:112} WARNING - /home/***/.local/lib/python3.12/site-packages/***/task/task_runner/standard_task_runner.py:70: DeprecationWarning: This process (pid=125) is multi-threaded, use of fork() may lead to deadlocks in the child.
  pid = os.fork()

[2025-01-24T00:26:04.233+0000] {standard_task_runner.py:72} INFO - Started process 126 to run task
[2025-01-24T00:26:04.233+0000] {standard_task_runner.py:104} INFO - Running: ['***', 'tasks', 'run', 'nasa_dag', 'extract_data', 'manual__2025-01-22T03:28:41.301915+00:00', '--job-id', '62', '--raw', '--subdir', 'DAGS_FOLDER/nasa_dag.py', '--cfg-path', '/tmp/tmp4heb3j2l']
[2025-01-24T00:26:04.234+0000] {standard_task_runner.py:105} INFO - Job 62: Subtask extract_data
[2025-01-24T00:26:04.270+0000] {task_command.py:467} INFO - Running <TaskInstance: nasa_dag.extract_data manual__2025-01-22T03:28:41.301915+00:00 [running]> on host 530245d0e6c7
[2025-01-24T00:26:04.337+0000] {taskinstance.py:3131} INFO - Exporting env vars: AIRFLOW_CTX_DAG_EMAIL='milo0@gmail.com' AIRFLOW_CTX_DAG_OWNER='camilo' AIRFLOW_CTX_DAG_ID='nasa_dag' AIRFLOW_CTX_TASK_ID='extract_data' AIRFLOW_CTX_EXECUTION_DATE='2025-01-22T03:28:41.301915+00:00' AIRFLOW_CTX_TRY_NUMBER='1' AIRFLOW_CTX_DAG_RUN_ID='manual__2025-01-22T03:28:41.301915+00:00'
[2025-01-24T00:26:04.338+0000] {taskinstance.py:731} INFO - ::endgroup::
[2025-01-24T00:26:04.350+0000] {subprocess.py:63} INFO - Tmp dir root location: /tmp
[2025-01-24T00:26:04.351+0000] {subprocess.py:75} INFO - Running command: ['/usr/bin/bash', '-c', 'python /opt/***/tmp/extract_api_nasa.py']
[2025-01-24T00:26:04.359+0000] {subprocess.py:86} INFO - Output:
[2025-01-24T00:26:07.273+0000] {subprocess.py:93} INFO - {'copyright': 'Mike Selby', 'date': '2025-01-23', 'explanation': 'Point your telescope toward the high flying constellation Pegasus and you can find this cosmic expanse of Milky Way stars and distant galaxies. NGC 7814 is centered in the sharp field of view that would almost be covered by a full moon. NGC 7814 is sometimes called the Little Sombrero for its resemblance to the brighter more famous M104, the Sombrero Galaxy. Both Sombrero and Little Sombrero are spiral galaxies seen edge-on, and both have extensive halos and central bulges cut by a thin disk with thinner dust lanes in silhouette. In fact, NGC 7814 is some 40 million light-years away and an estimated 60,000 light-years across. That actually makes the Little Sombrero about the same physical size as its better known namesake, appearing smaller and fainter only because it is farther away.', 'hdurl': 'https://apod.nasa.gov/apod/image/2501/NGC_7814_LRGB_crop-rev-1.jpg', 'media_type': 'image', 'service_version': 'v1', 'title': 'NGC 7814: Little Sombrero', 'url': 'https://apod.nasa.gov/apod/image/2501/NGC_7814_crop-rev-1_1024.jpg'}
[2025-01-24T00:26:07.273+0000] {subprocess.py:93} INFO - Traceback (most recent call last):
[2025-01-24T00:26:07.274+0000] {subprocess.py:93} INFO -   File "/opt/***/tmp/extract_api_nasa.py", line 35, in <module>
[2025-01-24T00:26:07.274+0000] {subprocess.py:93} INFO -     datos = json.load(archivo)
[2025-01-24T00:26:07.275+0000] {subprocess.py:93} INFO -             ^^^^^^^^^^^^^^^^^^
[2025-01-24T00:26:07.276+0000] {subprocess.py:93} INFO -   File "/usr/local/lib/python3.12/json/__init__.py", line 293, in load
[2025-01-24T00:26:07.276+0000] {subprocess.py:93} INFO -     return loads(fp.read(),
[2025-01-24T00:26:07.277+0000] {subprocess.py:93} INFO -            ^^^^^^^^^^^^^^^^
[2025-01-24T00:26:07.277+0000] {subprocess.py:93} INFO -   File "/usr/local/lib/python3.12/json/__init__.py", line 346, in loads
[2025-01-24T00:26:07.277+0000] {subprocess.py:93} INFO -     return _default_decoder.decode(s)
[2025-01-24T00:26:07.278+0000] {subprocess.py:93} INFO -            ^^^^^^^^^^^^^^^^^^^^^^^^^^
[2025-01-24T00:26:07.278+0000] {subprocess.py:93} INFO -   File "/usr/local/lib/python3.12/json/decoder.py", line 337, in decode
[2025-01-24T00:26:07.278+0000] {subprocess.py:93} INFO -     obj, end = self.raw_decode(s, idx=_w(s, 0).end())
[2025-01-24T00:26:07.279+0000] {subprocess.py:93} INFO -                ^^^^^^^^^^^^^^^^^^^^^^^^^^^^^^^^^^^^^^
[2025-01-24T00:26:07.279+0000] {subprocess.py:93} INFO -   File "/usr/local/lib/python3.12/json/decoder.py", line 355, in raw_decode
[2025-01-24T00:26:07.279+0000] {subprocess.py:93} INFO -     raise JSONDecodeError("Expecting value", s, err.value) from None
[2025-01-24T00:26:07.279+0000] {subprocess.py:93} INFO - json.decoder.JSONDecodeError: Expecting value: line 1 column 1 (char 0)
[2025-01-24T00:26:07.305+0000] {subprocess.py:97} INFO - Command exited with return code 1
[2025-01-24T00:26:07.313+0000] {taskinstance.py:3310} ERROR - Task failed with exception
Traceback (most recent call last):
  File "/home/airflow/.local/lib/python3.12/site-packages/airflow/models/taskinstance.py", line 767, in _execute_task
    result = _execute_callable(context=context, **execute_callable_kwargs)
             ^^^^^^^^^^^^^^^^^^^^^^^^^^^^^^^^^^^^^^^^^^^^^^^^^^^^^^^^^^^^^
  File "/home/airflow/.local/lib/python3.12/site-packages/airflow/models/taskinstance.py", line 733, in _execute_callable
    return ExecutionCallableRunner(
           ^^^^^^^^^^^^^^^^^^^^^^^^
  File "/home/airflow/.local/lib/python3.12/site-packages/airflow/utils/operator_helpers.py", line 252, in run
    return self.func(*args, **kwargs)
           ^^^^^^^^^^^^^^^^^^^^^^^^^^
  File "/home/airflow/.local/lib/python3.12/site-packages/airflow/models/baseoperator.py", line 406, in wrapper
    return func(self, *args, **kwargs)
           ^^^^^^^^^^^^^^^^^^^^^^^^^^^
  File "/home/airflow/.local/lib/python3.12/site-packages/airflow/operators/bash.py", line 249, in execute
    raise AirflowException(
airflow.exceptions.AirflowException: Bash command failed. The command returned a non-zero exit code 1.
[2025-01-24T00:26:07.321+0000] {taskinstance.py:1225} INFO - Marking task as UP_FOR_RETRY. dag_id=nasa_dag, task_id=extract_data, run_id=manual__2025-01-22T03:28:41.301915+00:00, execution_date=20250122T032841, start_date=20250124T002604, end_date=20250124T002607
[2025-01-24T00:26:07.334+0000] {taskinstance.py:340} INFO - ::group::Post task execution logs
[2025-01-24T00:26:07.335+0000] {standard_task_runner.py:124} ERROR - Failed to execute job 62 for task extract_data (Bash command failed. The command returned a non-zero exit code 1.; 126)
Traceback (most recent call last):
  File "/home/airflow/.local/lib/python3.12/site-packages/airflow/task/task_runner/standard_task_runner.py", line 117, in _start_by_fork
    ret = args.func(args, dag=self.dag)
          ^^^^^^^^^^^^^^^^^^^^^^^^^^^^^
  File "/home/airflow/.local/lib/python3.12/site-packages/airflow/cli/cli_config.py", line 49, in command
    return func(*args, **kwargs)
           ^^^^^^^^^^^^^^^^^^^^^
  File "/home/airflow/.local/lib/python3.12/site-packages/airflow/utils/cli.py", line 115, in wrapper
    return f(*args, **kwargs)
           ^^^^^^^^^^^^^^^^^^
  File "/home/airflow/.local/lib/python3.12/site-packages/airflow/cli/commands/task_command.py", line 483, in task_run
    task_return_code = _run_task_by_selected_method(args, _dag, ti)
                       ^^^^^^^^^^^^^^^^^^^^^^^^^^^^^^^^^^^^^^^^^^^^
  File "/home/airflow/.local/lib/python3.12/site-packages/airflow/cli/commands/task_command.py", line 256, in _run_task_by_selected_method
    return _run_raw_task(args, ti)
           ^^^^^^^^^^^^^^^^^^^^^^^
  File "/home/airflow/.local/lib/python3.12/site-packages/airflow/cli/commands/task_command.py", line 341, in _run_raw_task
    return ti._run_raw_task(
           ^^^^^^^^^^^^^^^^^
  File "/home/airflow/.local/lib/python3.12/site-packages/airflow/utils/session.py", line 97, in wrapper
    return func(*args, session=session, **kwargs)
           ^^^^^^^^^^^^^^^^^^^^^^^^^^^^^^^^^^^^^^
  File "/home/airflow/.local/lib/python3.12/site-packages/airflow/models/taskinstance.py", line 3004, in _run_raw_task
    return _run_raw_task(
           ^^^^^^^^^^^^^^
  File "/home/airflow/.local/lib/python3.12/site-packages/airflow/models/taskinstance.py", line 273, in _run_raw_task
    TaskInstance._execute_task_with_callbacks(
  File "/home/airflow/.local/lib/python3.12/site-packages/airflow/models/taskinstance.py", line 3158, in _execute_task_with_callbacks
    result = self._execute_task(context, task_orig)
             ^^^^^^^^^^^^^^^^^^^^^^^^^^^^^^^^^^^^^^
  File "/home/airflow/.local/lib/python3.12/site-packages/airflow/models/taskinstance.py", line 3182, in _execute_task
    return _execute_task(self, context, task_orig)
           ^^^^^^^^^^^^^^^^^^^^^^^^^^^^^^^^^^^^^^^
  File "/home/airflow/.local/lib/python3.12/site-packages/airflow/models/taskinstance.py", line 767, in _execute_task
    result = _execute_callable(context=context, **execute_callable_kwargs)
             ^^^^^^^^^^^^^^^^^^^^^^^^^^^^^^^^^^^^^^^^^^^^^^^^^^^^^^^^^^^^^
  File "/home/airflow/.local/lib/python3.12/site-packages/airflow/models/taskinstance.py", line 733, in _execute_callable
    return ExecutionCallableRunner(
           ^^^^^^^^^^^^^^^^^^^^^^^^
  File "/home/airflow/.local/lib/python3.12/site-packages/airflow/utils/operator_helpers.py", line 252, in run
    return self.func(*args, **kwargs)
           ^^^^^^^^^^^^^^^^^^^^^^^^^^
  File "/home/airflow/.local/lib/python3.12/site-packages/airflow/models/baseoperator.py", line 406, in wrapper
    return func(self, *args, **kwargs)
           ^^^^^^^^^^^^^^^^^^^^^^^^^^^
  File "/home/airflow/.local/lib/python3.12/site-packages/airflow/operators/bash.py", line 249, in execute
    raise AirflowException(
airflow.exceptions.AirflowException: Bash command failed. The command returned a non-zero exit code 1.
[2025-01-24T00:26:07.344+0000] {local_task_job_runner.py:266} INFO - Task exited with return code 1
[2025-01-24T00:26:07.362+0000] {taskinstance.py:3900} INFO - 0 downstream tasks scheduled from follow-on schedule check
[2025-01-24T00:26:07.363+0000] {local_task_job_runner.py:245} INFO - ::endgroup::
