[2025-02-05T02:29:24.983+0000] {local_task_job_runner.py:123} INFO - ::group::Pre task execution logs
[2025-02-05T02:29:24.996+0000] {taskinstance.py:2612} INFO - Dependencies all met for dep_context=non-requeueable deps ti=<TaskInstance: nasa_dag.create_data scheduled__2025-02-05T01:00:00+00:00 [queued]>
[2025-02-05T02:29:25.003+0000] {taskinstance.py:2612} INFO - Dependencies all met for dep_context=requeueable deps ti=<TaskInstance: nasa_dag.create_data scheduled__2025-02-05T01:00:00+00:00 [queued]>
[2025-02-05T02:29:25.003+0000] {taskinstance.py:2865} INFO - Starting attempt 1 of 1
[2025-02-05T02:29:25.015+0000] {taskinstance.py:2888} INFO - Executing <Task(MongoDBOperator): create_data> on 2025-02-05 01:00:00+00:00
[2025-02-05T02:29:25.019+0000] {warnings.py:112} WARNING - /home/***/.local/lib/python3.12/site-packages/***/task/task_runner/standard_task_runner.py:70: DeprecationWarning: This process (pid=75) is multi-threaded, use of fork() may lead to deadlocks in the child.
  pid = os.fork()

[2025-02-05T02:29:25.021+0000] {standard_task_runner.py:72} INFO - Started process 76 to run task
[2025-02-05T02:29:25.021+0000] {standard_task_runner.py:104} INFO - Running: ['***', 'tasks', 'run', 'nasa_dag', 'create_data', 'scheduled__2025-02-05T01:00:00+00:00', '--job-id', '284', '--raw', '--subdir', 'DAGS_FOLDER/nasa_dag.py', '--cfg-path', '/tmp/tmpnlx0xgfq']
[2025-02-05T02:29:25.022+0000] {standard_task_runner.py:105} INFO - Job 284: Subtask create_data
[2025-02-05T02:29:25.065+0000] {task_command.py:467} INFO - Running <TaskInstance: nasa_dag.create_data scheduled__2025-02-05T01:00:00+00:00 [running]> on host fbf16bed15ba
[2025-02-05T02:29:25.132+0000] {taskinstance.py:3131} INFO - Exporting env vars: AIRFLOW_CTX_DAG_OWNER='***' AIRFLOW_CTX_DAG_ID='nasa_dag' AIRFLOW_CTX_TASK_ID='create_data' AIRFLOW_CTX_EXECUTION_DATE='2025-02-05T01:00:00+00:00' AIRFLOW_CTX_TRY_NUMBER='1' AIRFLOW_CTX_DAG_RUN_ID='scheduled__2025-02-05T01:00:00+00:00'
[2025-02-05T02:29:25.133+0000] {taskinstance.py:731} INFO - ::endgroup::
[2025-02-05T02:29:25.155+0000] {base.py:84} INFO - Retrieving connection 'mongo_default'
[2025-02-05T02:29:55.407+0000] {taskinstance.py:3310} ERROR - Task failed with exception
Traceback (most recent call last):
  File "/home/airflow/.local/lib/python3.12/site-packages/airflow/models/taskinstance.py", line 767, in _execute_task
    result = _execute_callable(context=context, **execute_callable_kwargs)
             ^^^^^^^^^^^^^^^^^^^^^^^^^^^^^^^^^^^^^^^^^^^^^^^^^^^^^^^^^^^^^
  File "/home/airflow/.local/lib/python3.12/site-packages/airflow/models/taskinstance.py", line 733, in _execute_callable
    return ExecutionCallableRunner(
           ^^^^^^^^^^^^^^^^^^^^^^^^
  File "/home/airflow/.local/lib/python3.12/site-packages/airflow/utils/operator_helpers.py", line 252, in run
    return self.func(*args, **kwargs)
           ^^^^^^^^^^^^^^^^^^^^^^^^^^
  File "/home/airflow/.local/lib/python3.12/site-packages/airflow/models/baseoperator.py", line 406, in wrapper
    return func(self, *args, **kwargs)
           ^^^^^^^^^^^^^^^^^^^^^^^^^^^
  File "/opt/airflow/plugins/operators/mongodb_file_operator.py", line 34, in execute
    if self.collection not in db.list_collection_names():
                              ^^^^^^^^^^^^^^^^^^^^^^^^^^
  File "/home/airflow/.local/lib/python3.12/site-packages/pymongo/synchronous/database.py", line 1226, in list_collection_names
    return self._list_collection_names(session, filter, comment, **kwargs)
           ^^^^^^^^^^^^^^^^^^^^^^^^^^^^^^^^^^^^^^^^^^^^^^^^^^^^^^^^^^^^^^^
  File "/home/airflow/.local/lib/python3.12/site-packages/pymongo/synchronous/database.py", line 1191, in _list_collection_names
    result["name"] for result in self._list_collections_helper(session=session, **kwargs)
                                 ^^^^^^^^^^^^^^^^^^^^^^^^^^^^^^^^^^^^^^^^^^^^^^^^^^^^^^^^
  File "/home/airflow/.local/lib/python3.12/site-packages/pymongo/synchronous/database.py", line 1138, in _list_collections_helper
    return self._client._retryable_read(
           ^^^^^^^^^^^^^^^^^^^^^^^^^^^^^
  File "/home/airflow/.local/lib/python3.12/site-packages/pymongo/synchronous/mongo_client.py", line 1863, in _retryable_read
    return self._retry_internal(
           ^^^^^^^^^^^^^^^^^^^^^
  File "/home/airflow/.local/lib/python3.12/site-packages/pymongo/_csot.py", line 119, in csot_wrapper
    return func(self, *args, **kwargs)
           ^^^^^^^^^^^^^^^^^^^^^^^^^^^
  File "/home/airflow/.local/lib/python3.12/site-packages/pymongo/synchronous/mongo_client.py", line 1830, in _retry_internal
    ).run()
      ^^^^^
  File "/home/airflow/.local/lib/python3.12/site-packages/pymongo/synchronous/mongo_client.py", line 2554, in run
    return self._read() if self._is_read else self._write()
           ^^^^^^^^^^^^
  File "/home/airflow/.local/lib/python3.12/site-packages/pymongo/synchronous/mongo_client.py", line 2689, in _read
    self._server = self._get_server()
                   ^^^^^^^^^^^^^^^^^^
  File "/home/airflow/.local/lib/python3.12/site-packages/pymongo/synchronous/mongo_client.py", line 2645, in _get_server
    return self._client._select_server(
           ^^^^^^^^^^^^^^^^^^^^^^^^^^^^
  File "/home/airflow/.local/lib/python3.12/site-packages/pymongo/synchronous/mongo_client.py", line 1649, in _select_server
    server = topology.select_server(
             ^^^^^^^^^^^^^^^^^^^^^^^
  File "/home/airflow/.local/lib/python3.12/site-packages/pymongo/synchronous/topology.py", line 398, in select_server
    server = self._select_server(
             ^^^^^^^^^^^^^^^^^^^^
  File "/home/airflow/.local/lib/python3.12/site-packages/pymongo/synchronous/topology.py", line 376, in _select_server
    servers = self.select_servers(
              ^^^^^^^^^^^^^^^^^^^^
  File "/home/airflow/.local/lib/python3.12/site-packages/pymongo/synchronous/topology.py", line 283, in select_servers
    server_descriptions = self._select_servers_loop(
                          ^^^^^^^^^^^^^^^^^^^^^^^^^^
  File "/home/airflow/.local/lib/python3.12/site-packages/pymongo/synchronous/topology.py", line 333, in _select_servers_loop
    raise ServerSelectionTimeoutError(
pymongo.errors.ServerSelectionTimeoutError: host.docker.internal:27017: [Errno 101] Network is unreachable (configured timeouts: socketTimeoutMS: 20000.0ms, connectTimeoutMS: 20000.0ms), Timeout: 30s, Topology Description: <TopologyDescription id: 67a2cd05a804ee1aac7e87fe, topology_type: Unknown, servers: [<ServerDescription ('host.docker.internal', 27017) server_type: Unknown, rtt: None, error=AutoReconnect('host.docker.internal:27017: [Errno 101] Network is unreachable (configured timeouts: socketTimeoutMS: 20000.0ms, connectTimeoutMS: 20000.0ms)')>]>
[2025-02-05T02:29:55.417+0000] {taskinstance.py:1225} INFO - Marking task as FAILED. dag_id=nasa_dag, task_id=create_data, run_id=scheduled__2025-02-05T01:00:00+00:00, execution_date=20250205T010000, start_date=20250205T022924, end_date=20250205T022955
[2025-02-05T02:29:55.427+0000] {taskinstance.py:340} INFO - ::group::Post task execution logs
[2025-02-05T02:29:55.428+0000] {standard_task_runner.py:124} ERROR - Failed to execute job 284 for task create_data (host.docker.internal:27017: [Errno 101] Network is unreachable (configured timeouts: socketTimeoutMS: 20000.0ms, connectTimeoutMS: 20000.0ms), Timeout: 30s, Topology Description: <TopologyDescription id: 67a2cd05a804ee1aac7e87fe, topology_type: Unknown, servers: [<ServerDescription ('host.docker.internal', 27017) server_type: Unknown, rtt: None, error=AutoReconnect('host.docker.internal:27017: [Errno 101] Network is unreachable (configured timeouts: socketTimeoutMS: 20000.0ms, connectTimeoutMS: 20000.0ms)')>]>; 76)
Traceback (most recent call last):
  File "/home/airflow/.local/lib/python3.12/site-packages/airflow/task/task_runner/standard_task_runner.py", line 117, in _start_by_fork
    ret = args.func(args, dag=self.dag)
          ^^^^^^^^^^^^^^^^^^^^^^^^^^^^^
  File "/home/airflow/.local/lib/python3.12/site-packages/airflow/cli/cli_config.py", line 49, in command
    return func(*args, **kwargs)
           ^^^^^^^^^^^^^^^^^^^^^
  File "/home/airflow/.local/lib/python3.12/site-packages/airflow/utils/cli.py", line 115, in wrapper
    return f(*args, **kwargs)
           ^^^^^^^^^^^^^^^^^^
  File "/home/airflow/.local/lib/python3.12/site-packages/airflow/cli/commands/task_command.py", line 483, in task_run
    task_return_code = _run_task_by_selected_method(args, _dag, ti)
                       ^^^^^^^^^^^^^^^^^^^^^^^^^^^^^^^^^^^^^^^^^^^^
  File "/home/airflow/.local/lib/python3.12/site-packages/airflow/cli/commands/task_command.py", line 256, in _run_task_by_selected_method
    return _run_raw_task(args, ti)
           ^^^^^^^^^^^^^^^^^^^^^^^
  File "/home/airflow/.local/lib/python3.12/site-packages/airflow/cli/commands/task_command.py", line 341, in _run_raw_task
    return ti._run_raw_task(
           ^^^^^^^^^^^^^^^^^
  File "/home/airflow/.local/lib/python3.12/site-packages/airflow/utils/session.py", line 97, in wrapper
    return func(*args, session=session, **kwargs)
           ^^^^^^^^^^^^^^^^^^^^^^^^^^^^^^^^^^^^^^
  File "/home/airflow/.local/lib/python3.12/site-packages/airflow/models/taskinstance.py", line 3004, in _run_raw_task
    return _run_raw_task(
           ^^^^^^^^^^^^^^
  File "/home/airflow/.local/lib/python3.12/site-packages/airflow/models/taskinstance.py", line 273, in _run_raw_task
    TaskInstance._execute_task_with_callbacks(
  File "/home/airflow/.local/lib/python3.12/site-packages/airflow/models/taskinstance.py", line 3158, in _execute_task_with_callbacks
    result = self._execute_task(context, task_orig)
             ^^^^^^^^^^^^^^^^^^^^^^^^^^^^^^^^^^^^^^
  File "/home/airflow/.local/lib/python3.12/site-packages/airflow/models/taskinstance.py", line 3182, in _execute_task
    return _execute_task(self, context, task_orig)
           ^^^^^^^^^^^^^^^^^^^^^^^^^^^^^^^^^^^^^^^
  File "/home/airflow/.local/lib/python3.12/site-packages/airflow/models/taskinstance.py", line 767, in _execute_task
    result = _execute_callable(context=context, **execute_callable_kwargs)
             ^^^^^^^^^^^^^^^^^^^^^^^^^^^^^^^^^^^^^^^^^^^^^^^^^^^^^^^^^^^^^
  File "/home/airflow/.local/lib/python3.12/site-packages/airflow/models/taskinstance.py", line 733, in _execute_callable
    return ExecutionCallableRunner(
           ^^^^^^^^^^^^^^^^^^^^^^^^
  File "/home/airflow/.local/lib/python3.12/site-packages/airflow/utils/operator_helpers.py", line 252, in run
    return self.func(*args, **kwargs)
           ^^^^^^^^^^^^^^^^^^^^^^^^^^
  File "/home/airflow/.local/lib/python3.12/site-packages/airflow/models/baseoperator.py", line 406, in wrapper
    return func(self, *args, **kwargs)
           ^^^^^^^^^^^^^^^^^^^^^^^^^^^
  File "/opt/airflow/plugins/operators/mongodb_file_operator.py", line 34, in execute
    if self.collection not in db.list_collection_names():
                              ^^^^^^^^^^^^^^^^^^^^^^^^^^
  File "/home/airflow/.local/lib/python3.12/site-packages/pymongo/synchronous/database.py", line 1226, in list_collection_names
    return self._list_collection_names(session, filter, comment, **kwargs)
           ^^^^^^^^^^^^^^^^^^^^^^^^^^^^^^^^^^^^^^^^^^^^^^^^^^^^^^^^^^^^^^^
  File "/home/airflow/.local/lib/python3.12/site-packages/pymongo/synchronous/database.py", line 1191, in _list_collection_names
    result["name"] for result in self._list_collections_helper(session=session, **kwargs)
                                 ^^^^^^^^^^^^^^^^^^^^^^^^^^^^^^^^^^^^^^^^^^^^^^^^^^^^^^^^
  File "/home/airflow/.local/lib/python3.12/site-packages/pymongo/synchronous/database.py", line 1138, in _list_collections_helper
    return self._client._retryable_read(
           ^^^^^^^^^^^^^^^^^^^^^^^^^^^^^
  File "/home/airflow/.local/lib/python3.12/site-packages/pymongo/synchronous/mongo_client.py", line 1863, in _retryable_read
    return self._retry_internal(
           ^^^^^^^^^^^^^^^^^^^^^
  File "/home/airflow/.local/lib/python3.12/site-packages/pymongo/_csot.py", line 119, in csot_wrapper
    return func(self, *args, **kwargs)
           ^^^^^^^^^^^^^^^^^^^^^^^^^^^
  File "/home/airflow/.local/lib/python3.12/site-packages/pymongo/synchronous/mongo_client.py", line 1830, in _retry_internal
    ).run()
      ^^^^^
  File "/home/airflow/.local/lib/python3.12/site-packages/pymongo/synchronous/mongo_client.py", line 2554, in run
    return self._read() if self._is_read else self._write()
           ^^^^^^^^^^^^
  File "/home/airflow/.local/lib/python3.12/site-packages/pymongo/synchronous/mongo_client.py", line 2689, in _read
    self._server = self._get_server()
                   ^^^^^^^^^^^^^^^^^^
  File "/home/airflow/.local/lib/python3.12/site-packages/pymongo/synchronous/mongo_client.py", line 2645, in _get_server
    return self._client._select_server(
           ^^^^^^^^^^^^^^^^^^^^^^^^^^^^
  File "/home/airflow/.local/lib/python3.12/site-packages/pymongo/synchronous/mongo_client.py", line 1649, in _select_server
    server = topology.select_server(
             ^^^^^^^^^^^^^^^^^^^^^^^
  File "/home/airflow/.local/lib/python3.12/site-packages/pymongo/synchronous/topology.py", line 398, in select_server
    server = self._select_server(
             ^^^^^^^^^^^^^^^^^^^^
  File "/home/airflow/.local/lib/python3.12/site-packages/pymongo/synchronous/topology.py", line 376, in _select_server
    servers = self.select_servers(
              ^^^^^^^^^^^^^^^^^^^^
  File "/home/airflow/.local/lib/python3.12/site-packages/pymongo/synchronous/topology.py", line 283, in select_servers
    server_descriptions = self._select_servers_loop(
                          ^^^^^^^^^^^^^^^^^^^^^^^^^^
  File "/home/airflow/.local/lib/python3.12/site-packages/pymongo/synchronous/topology.py", line 333, in _select_servers_loop
    raise ServerSelectionTimeoutError(
pymongo.errors.ServerSelectionTimeoutError: host.docker.internal:27017: [Errno 101] Network is unreachable (configured timeouts: socketTimeoutMS: 20000.0ms, connectTimeoutMS: 20000.0ms), Timeout: 30s, Topology Description: <TopologyDescription id: 67a2cd05a804ee1aac7e87fe, topology_type: Unknown, servers: [<ServerDescription ('host.docker.internal', 27017) server_type: Unknown, rtt: None, error=AutoReconnect('host.docker.internal:27017: [Errno 101] Network is unreachable (configured timeouts: socketTimeoutMS: 20000.0ms, connectTimeoutMS: 20000.0ms)')>]>
[2025-02-05T02:29:55.473+0000] {local_task_job_runner.py:266} INFO - Task exited with return code 1
[2025-02-05T02:29:55.489+0000] {taskinstance.py:3900} INFO - 0 downstream tasks scheduled from follow-on schedule check
[2025-02-05T02:29:55.494+0000] {local_task_job_runner.py:245} INFO - ::endgroup::
