[2025-01-22T03:27:42.384+0000] {local_task_job_runner.py:123} INFO - ::group::Pre task execution logs
[2025-01-22T03:27:42.395+0000] {taskinstance.py:2612} INFO - Dependencies all met for dep_context=non-requeueable deps ti=<TaskInstance: nasa_dag.extract_data manual__2025-01-22T03:27:34.651895+00:00 [queued]>
[2025-01-22T03:27:42.400+0000] {taskinstance.py:2612} INFO - Dependencies all met for dep_context=requeueable deps ti=<TaskInstance: nasa_dag.extract_data manual__2025-01-22T03:27:34.651895+00:00 [queued]>
[2025-01-22T03:27:42.401+0000] {taskinstance.py:2865} INFO - Starting attempt 1 of 2
[2025-01-22T03:27:42.409+0000] {taskinstance.py:2888} INFO - Executing <Task(BashOperator): extract_data> on 2025-01-22 03:27:34.651895+00:00
[2025-01-22T03:27:42.414+0000] {warnings.py:112} WARNING - /home/***/.local/lib/python3.12/site-packages/***/task/task_runner/standard_task_runner.py:70: DeprecationWarning: This process (pid=103) is multi-threaded, use of fork() may lead to deadlocks in the child.
  pid = os.fork()

[2025-01-22T03:27:42.415+0000] {standard_task_runner.py:72} INFO - Started process 104 to run task
[2025-01-22T03:27:42.415+0000] {standard_task_runner.py:104} INFO - Running: ['***', 'tasks', 'run', 'nasa_dag', 'extract_data', 'manual__2025-01-22T03:27:34.651895+00:00', '--job-id', '58', '--raw', '--subdir', 'DAGS_FOLDER/nasa_dag.py', '--cfg-path', '/tmp/tmp1170jmvj']
[2025-01-22T03:27:42.416+0000] {standard_task_runner.py:105} INFO - Job 58: Subtask extract_data
[2025-01-22T03:27:42.448+0000] {task_command.py:467} INFO - Running <TaskInstance: nasa_dag.extract_data manual__2025-01-22T03:27:34.651895+00:00 [running]> on host 530245d0e6c7
[2025-01-22T03:27:42.505+0000] {taskinstance.py:3131} INFO - Exporting env vars: AIRFLOW_CTX_DAG_EMAIL='milo0@gmail.com' AIRFLOW_CTX_DAG_OWNER='camilo' AIRFLOW_CTX_DAG_ID='nasa_dag' AIRFLOW_CTX_TASK_ID='extract_data' AIRFLOW_CTX_EXECUTION_DATE='2025-01-22T03:27:34.651895+00:00' AIRFLOW_CTX_TRY_NUMBER='1' AIRFLOW_CTX_DAG_RUN_ID='manual__2025-01-22T03:27:34.651895+00:00'
[2025-01-22T03:27:42.506+0000] {taskinstance.py:731} INFO - ::endgroup::
[2025-01-22T03:27:42.516+0000] {subprocess.py:63} INFO - Tmp dir root location: /tmp
[2025-01-22T03:27:42.517+0000] {subprocess.py:75} INFO - Running command: ['/usr/bin/bash', '-c', 'python /opt/***/tmp/extract_api_nasa.py']
[2025-01-22T03:27:42.523+0000] {subprocess.py:86} INFO - Output:
[2025-01-22T03:27:44.724+0000] {subprocess.py:93} INFO - {'date': '2025-01-21', 'explanation': "What's that in the sky? Above the city, above most clouds, far in the distance: it's a comet. Pictured, the impressive tail of Comet C/2024 G3 (ATLAS) was imaged from Brasília, Brazil four days ago. Last week the evolving  comet rounded the Sun well inside the orbit of planet Mercury, going so close there was early concern that it might break up -- and recent evidence that it really did.  At one point near perihelion, Comet ATLAS was so bright that sightings were even reported during the day -- over the bright sky near the Sun -- by careful observers.  Over the past few days, Comet ATLAS has developed a long tail that has been partly visible with unaided eyes after sunset, most notably in Earth's southern hemisphere.    Growing Gallery: Comet ATLAS (G3)", 'hdurl': 'https://apod.nasa.gov/apod/image/2501/CometATLAS_Danin_1080.jpg', 'media_type': 'image', 'service_version': 'v1', 'title': 'Comet ATLAS over Brasília', 'url': 'https://apod.nasa.gov/apod/image/2501/CometATLAS_Danin_1080.jpg'}
[2025-01-22T03:27:44.725+0000] {subprocess.py:93} INFO - Traceback (most recent call last):
[2025-01-22T03:27:44.725+0000] {subprocess.py:93} INFO -   File "/opt/***/tmp/extract_api_nasa.py", line 35, in <module>
[2025-01-22T03:27:44.726+0000] {subprocess.py:93} INFO -     datos = json.load(archivo)
[2025-01-22T03:27:44.726+0000] {subprocess.py:93} INFO -             ^^^^^^^^^^^^^^^^^^
[2025-01-22T03:27:44.726+0000] {subprocess.py:93} INFO -   File "/usr/local/lib/python3.12/json/__init__.py", line 293, in load
[2025-01-22T03:27:44.727+0000] {subprocess.py:93} INFO -     return loads(fp.read(),
[2025-01-22T03:27:44.727+0000] {subprocess.py:93} INFO -            ^^^^^^^^^^^^^^^^
[2025-01-22T03:27:44.728+0000] {subprocess.py:93} INFO -   File "/usr/local/lib/python3.12/json/__init__.py", line 346, in loads
[2025-01-22T03:27:44.728+0000] {subprocess.py:93} INFO -     return _default_decoder.decode(s)
[2025-01-22T03:27:44.728+0000] {subprocess.py:93} INFO -            ^^^^^^^^^^^^^^^^^^^^^^^^^^
[2025-01-22T03:27:44.729+0000] {subprocess.py:93} INFO -   File "/usr/local/lib/python3.12/json/decoder.py", line 337, in decode
[2025-01-22T03:27:44.729+0000] {subprocess.py:93} INFO -     obj, end = self.raw_decode(s, idx=_w(s, 0).end())
[2025-01-22T03:27:44.729+0000] {subprocess.py:93} INFO -                ^^^^^^^^^^^^^^^^^^^^^^^^^^^^^^^^^^^^^^
[2025-01-22T03:27:44.730+0000] {subprocess.py:93} INFO -   File "/usr/local/lib/python3.12/json/decoder.py", line 355, in raw_decode
[2025-01-22T03:27:44.730+0000] {subprocess.py:93} INFO -     raise JSONDecodeError("Expecting value", s, err.value) from None
[2025-01-22T03:27:44.731+0000] {subprocess.py:93} INFO - json.decoder.JSONDecodeError: Expecting value: line 1 column 1 (char 0)
[2025-01-22T03:27:44.760+0000] {subprocess.py:97} INFO - Command exited with return code 1
[2025-01-22T03:27:44.770+0000] {taskinstance.py:3310} ERROR - Task failed with exception
Traceback (most recent call last):
  File "/home/airflow/.local/lib/python3.12/site-packages/airflow/models/taskinstance.py", line 767, in _execute_task
    result = _execute_callable(context=context, **execute_callable_kwargs)
             ^^^^^^^^^^^^^^^^^^^^^^^^^^^^^^^^^^^^^^^^^^^^^^^^^^^^^^^^^^^^^
  File "/home/airflow/.local/lib/python3.12/site-packages/airflow/models/taskinstance.py", line 733, in _execute_callable
    return ExecutionCallableRunner(
           ^^^^^^^^^^^^^^^^^^^^^^^^
  File "/home/airflow/.local/lib/python3.12/site-packages/airflow/utils/operator_helpers.py", line 252, in run
    return self.func(*args, **kwargs)
           ^^^^^^^^^^^^^^^^^^^^^^^^^^
  File "/home/airflow/.local/lib/python3.12/site-packages/airflow/models/baseoperator.py", line 406, in wrapper
    return func(self, *args, **kwargs)
           ^^^^^^^^^^^^^^^^^^^^^^^^^^^
  File "/home/airflow/.local/lib/python3.12/site-packages/airflow/operators/bash.py", line 249, in execute
    raise AirflowException(
airflow.exceptions.AirflowException: Bash command failed. The command returned a non-zero exit code 1.
[2025-01-22T03:27:44.778+0000] {taskinstance.py:1225} INFO - Marking task as UP_FOR_RETRY. dag_id=nasa_dag, task_id=extract_data, run_id=manual__2025-01-22T03:27:34.651895+00:00, execution_date=20250122T032734, start_date=20250122T032742, end_date=20250122T032744
[2025-01-22T03:27:44.792+0000] {taskinstance.py:340} INFO - ::group::Post task execution logs
[2025-01-22T03:27:44.793+0000] {standard_task_runner.py:124} ERROR - Failed to execute job 58 for task extract_data (Bash command failed. The command returned a non-zero exit code 1.; 104)
Traceback (most recent call last):
  File "/home/airflow/.local/lib/python3.12/site-packages/airflow/task/task_runner/standard_task_runner.py", line 117, in _start_by_fork
    ret = args.func(args, dag=self.dag)
          ^^^^^^^^^^^^^^^^^^^^^^^^^^^^^
  File "/home/airflow/.local/lib/python3.12/site-packages/airflow/cli/cli_config.py", line 49, in command
    return func(*args, **kwargs)
           ^^^^^^^^^^^^^^^^^^^^^
  File "/home/airflow/.local/lib/python3.12/site-packages/airflow/utils/cli.py", line 115, in wrapper
    return f(*args, **kwargs)
           ^^^^^^^^^^^^^^^^^^
  File "/home/airflow/.local/lib/python3.12/site-packages/airflow/cli/commands/task_command.py", line 483, in task_run
    task_return_code = _run_task_by_selected_method(args, _dag, ti)
                       ^^^^^^^^^^^^^^^^^^^^^^^^^^^^^^^^^^^^^^^^^^^^
  File "/home/airflow/.local/lib/python3.12/site-packages/airflow/cli/commands/task_command.py", line 256, in _run_task_by_selected_method
    return _run_raw_task(args, ti)
           ^^^^^^^^^^^^^^^^^^^^^^^
  File "/home/airflow/.local/lib/python3.12/site-packages/airflow/cli/commands/task_command.py", line 341, in _run_raw_task
    return ti._run_raw_task(
           ^^^^^^^^^^^^^^^^^
  File "/home/airflow/.local/lib/python3.12/site-packages/airflow/utils/session.py", line 97, in wrapper
    return func(*args, session=session, **kwargs)
           ^^^^^^^^^^^^^^^^^^^^^^^^^^^^^^^^^^^^^^
  File "/home/airflow/.local/lib/python3.12/site-packages/airflow/models/taskinstance.py", line 3004, in _run_raw_task
    return _run_raw_task(
           ^^^^^^^^^^^^^^
  File "/home/airflow/.local/lib/python3.12/site-packages/airflow/models/taskinstance.py", line 273, in _run_raw_task
    TaskInstance._execute_task_with_callbacks(
  File "/home/airflow/.local/lib/python3.12/site-packages/airflow/models/taskinstance.py", line 3158, in _execute_task_with_callbacks
    result = self._execute_task(context, task_orig)
             ^^^^^^^^^^^^^^^^^^^^^^^^^^^^^^^^^^^^^^
  File "/home/airflow/.local/lib/python3.12/site-packages/airflow/models/taskinstance.py", line 3182, in _execute_task
    return _execute_task(self, context, task_orig)
           ^^^^^^^^^^^^^^^^^^^^^^^^^^^^^^^^^^^^^^^
  File "/home/airflow/.local/lib/python3.12/site-packages/airflow/models/taskinstance.py", line 767, in _execute_task
    result = _execute_callable(context=context, **execute_callable_kwargs)
             ^^^^^^^^^^^^^^^^^^^^^^^^^^^^^^^^^^^^^^^^^^^^^^^^^^^^^^^^^^^^^
  File "/home/airflow/.local/lib/python3.12/site-packages/airflow/models/taskinstance.py", line 733, in _execute_callable
    return ExecutionCallableRunner(
           ^^^^^^^^^^^^^^^^^^^^^^^^
  File "/home/airflow/.local/lib/python3.12/site-packages/airflow/utils/operator_helpers.py", line 252, in run
    return self.func(*args, **kwargs)
           ^^^^^^^^^^^^^^^^^^^^^^^^^^
  File "/home/airflow/.local/lib/python3.12/site-packages/airflow/models/baseoperator.py", line 406, in wrapper
    return func(self, *args, **kwargs)
           ^^^^^^^^^^^^^^^^^^^^^^^^^^^
  File "/home/airflow/.local/lib/python3.12/site-packages/airflow/operators/bash.py", line 249, in execute
    raise AirflowException(
airflow.exceptions.AirflowException: Bash command failed. The command returned a non-zero exit code 1.
[2025-01-22T03:27:44.806+0000] {local_task_job_runner.py:266} INFO - Task exited with return code 1
[2025-01-22T03:27:44.825+0000] {taskinstance.py:3900} INFO - 0 downstream tasks scheduled from follow-on schedule check
[2025-01-22T03:27:44.827+0000] {local_task_job_runner.py:245} INFO - ::endgroup::
